<?xml version="1.0" encoding="utf-8"?>
<!-- This URDF was automatically created by SolidWorks to URDF Exporter! Originally created by Stephen Brawner (brawner@gmail.com) 
     Commit Version: 1.5.1-0-g916b5db  Build Version: 1.5.7152.31018
     For more information, please see http://wiki.ros.org/sw_urdf_exporter -->
<robot
  name="MH5-URDF">
  <link
    name="base_link">
    <inertial>
      <origin
        xyz="-0.0110883019646767 0.000227788926138211 0.103150384989412"
        rpy="0 0 0" />
      <mass
        value="6.38321181493355" />
      <inertia
        ixx="0.0372965121749265"
        ixy="0.000165084088990519"
        ixz="-0.00045851126079573"
        iyy="0.0424283210142111"
        iyz="3.89226790922586E-05"
        izz="0.0312521171681315" />
    </inertial>
    <visual>
      <origin
        xyz="0 0 0"
        rpy="0 0 0" />
      <geometry>
        <mesh
          filename="package://MH5-URDF/meshes/base_link.STL" />
      </geometry>
      <material
        name="">
        <color
          rgba="0 0 1 1" />
      </material>
    </visual>
    <collision>
      <origin
        xyz="0 0 0"
        rpy="0 0 0" />
      <geometry>
        <mesh
          filename="package://MH5-URDF/meshes/base_link.STL" />
      </geometry>
    </collision>
  </link>
  <link
    name="link_s">
    <inertial>
      <origin
        xyz="0.00202948665386829 0.04176384850382 0.0808100983343647"
        rpy="0 0 0" />
      <mass
        value="3.06563145753173" />
      <inertia
        ixx="0.0174224038397614"
        ixy="-0.000319255372656743"
        ixz="-0.000351939431144338"
        iyy="0.012163240851605"
        iyz="-0.00550804303531142"
        izz="0.0129222149793393" />
    </inertial>
    <visual>
      <origin
        xyz="0 0 0"
        rpy="0 0 0" />
      <geometry>
        <mesh
          filename="package://MH5-URDF/meshes/link_s.STL" />
      </geometry>
      <material
        name="">
        <color
          rgba="0 0 1 1" />
      </material>
    </visual>
    <collision>
      <origin
        xyz="0 0 0"
        rpy="0 0 0" />
      <geometry>
        <mesh
          filename="package://MH5-URDF/meshes/link_s.STL" />
      </geometry>
    </collision>
  </link>
  <joint
    name="joint_s"
    type="revolute">
    <origin
      xyz="0 -0.199 0"
      rpy="1.5708 1.5708 0" />
    <parent
      link="base_link" />
    <child
      link="link_s" />
    <axis
      xyz="0 0 1" />
    <limit
      lower="-2.9671"
      upper="2.9671"
      effort="0"
      velocity="0" />
  </joint>
  <link
    name="link_l">
    <inertial>
      <origin
        xyz="0.000647316551126979 -0.00408188732835905 0.18535518260864"
        rpy="0 0 0" />
      <mass
        value="1.36278409878616" />
      <inertia
        ixx="0.0317559117871832"
        ixy="-0.000134908986237019"
        ixz="-0.000678776996235032"
        iyy="0.038117122383231"
        iyz="-0.000233953246022673"
        izz="0.0103349890416148" />
    </inertial>
    <visual>
      <origin
        xyz="0 0 0"
        rpy="0 0 0" />
      <geometry>
        <mesh
          filename="package://MH5-URDF/meshes/link_l.STL" />
      </geometry>
      <material
        name="">
        <color
          rgba="0 0 1 1" />
      </material>
    </visual>
    <collision>
      <origin
        xyz="0 0 0"
        rpy="0 0 0" />
      <geometry>
        <mesh
          filename="package://MH5-URDF/meshes/link_l.STL" />
      </geometry>
    </collision>
  </link>
  <joint
    name="joint_l"
    type="revolute">
    <origin
      xyz="0 0.088 0.131"
      rpy="0 0 0" />
    <parent
      link="link_s" />
    <child
      link="link_l" />
    <axis
      xyz="1 0 0" />
    <limit
      lower="-1.1345"
      upper="2.618"
      effort="0"
      velocity="0" />
  </joint>
  <link
    name="link_u">
    <inertial>
      <origin
        xyz="0.00116035645793911 -0.01041623965395 0.0190677964746967"
        rpy="0 0 0" />
      <mass
        value="2.53028013023471" />
      <inertia
        ixx="0.00860406610948572"
        ixy="-3.07058925892111E-05"
        ixz="3.19825365950595E-05"
        iyy="0.0068460116094622"
        iyz="-0.000743674699895537"
        izz="0.00762537326813849" />
    </inertial>
    <visual>
      <origin
        xyz="0 0 0"
        rpy="0 0 0" />
      <geometry>
        <mesh
          filename="package://MH5-URDF/meshes/link_u.STL" />
      </geometry>
      <material
        name="">
        <color
          rgba="0 0 1 1" />
      </material>
    </visual>
    <collision>
      <origin
        xyz="0 0 0"
        rpy="0 0 0" />
      <geometry>
        <mesh
          filename="package://MH5-URDF/meshes/link_u.STL" />
      </geometry>
    </collision>
  </link>
  <joint
    name="joint_u"
    type="revolute">
    <origin
      xyz="0 0 0.4"
      rpy="0 0 0" />
    <parent
      link="link_l" />
    <child
      link="link_u" />
    <axis
      xyz="1 0 0" />
    <limit
      lower="-2.4086"
      upper="4.4506"
      effort="0"
      velocity="0" />
  </joint>
  <link
    name="link_r">
    <inertial>
      <origin
        xyz="0.00704134923216865 0.167370198187689 0.000104623301099172"
        rpy="0 0 0" />
      <mass
        value="0.993705238857949" />
      <inertia
        ixx="0.0105281527461912"
        ixy="-0.000452680853064833"
        ixz="7.95336810316176E-06"
        iyy="0.00235359322695917"
        iyz="-7.6422999361452E-06"
        izz="0.0108820827309093" />
    </inertial>
    <visual>
      <origin
        xyz="0 0 0"
        rpy="0 0 0" />
      <geometry>
        <mesh
          filename="package://MH5-URDF/meshes/link_r.STL" />
      </geometry>
      <material
        name="">
        <color
          rgba="0 0 1 1" />
      </material>
    </visual>
    <collision>
      <origin
        xyz="0 0 0"
        rpy="0 0 0" />
      <geometry>
        <mesh
          filename="package://MH5-URDF/meshes/link_r.STL" />
      </geometry>
    </collision>
  </link>
  <joint
    name="joint_r"
    type="revolute">
    <origin
      xyz="0 0.0715 0.04"
      rpy="0 0 0" />
    <parent
      link="link_u" />
    <child
      link="link_r" />
    <axis
      xyz="0 1 0" />
    <limit
      lower="-3.3161"
      upper="3.3161"
      effort="0"
      velocity="0" />
  </joint>
  <link
    name="link_b">
    <inertial>
      <origin
        xyz="-3.31240579540506E-05 0.0192296605326606 8.25170175109413E-05"
        rpy="0 0 0" />
      <mass
        value="0.389442932956022" />
      <inertia
        ixx="0.000273042376978114"
        ixy="-7.84729964815532E-08"
        ixz="-3.45484102632551E-07"
        iyy="0.000242697433183168"
        iyz="-6.00305737513743E-07"
        izz="0.000255615504986072" />
    </inertial>
    <visual>
      <origin
        xyz="0 0 0"
        rpy="0 0 0" />
      <geometry>
        <mesh
          filename="package://MH5-URDF/meshes/link_b.STL" />
      </geometry>
      <material
        name="">
        <color
          rgba="0 0 1 1" />
      </material>
    </visual>
    <collision>
      <origin
        xyz="0 0 0"
        rpy="0 0 0" />
      <geometry>
        <mesh
          filename="package://MH5-URDF/meshes/link_b.STL" />
      </geometry>
    </collision>
  </link>
  <joint
    name="joint_b"
    type="revolute">
    <origin
      xyz="0 0.3335 0"
      rpy="0 0 0" />
    <parent
      link="link_r" />
    <child
      link="link_b" />
    <axis
      xyz="1 0 0" />
    <limit
      lower="-2.3562"
      upper="2.3562"
      effort="0"
      velocity="0" />
  </joint>
  <link
    name="link_t">
    <inertial>
      <origin
        xyz="-3.5221941675433E-16 0.0140262568274812 5.00761677482142E-05"
        rpy="0 0 0" />
      <mass
        value="0.0432292203100036" />
      <inertia
        ixx="8.23256012321425E-06"
        ixy="2.28075910136324E-21"
        ixz="7.60854499472136E-22"
        iyy="1.07676881315043E-05"
        iyz="-2.48378278463169E-08"
        izz="8.26676339636709E-06" />
    </inertial>
    <visual>
      <origin
        xyz="0 0 0"
        rpy="0 0 0" />
      <geometry>
        <mesh
          filename="package://MH5-URDF/meshes/link_t.STL" />
      </geometry>
      <material
        name="">
        <color
          rgba="0.866666666666667 0.701960784313725 0.345098039215686 1" />
      </material>
    </visual>
    <collision>
      <origin
        xyz="0 0 0"
        rpy="0 0 0" />
      <geometry>
        <mesh
          filename="package://MH5-URDF/meshes/link_t.STL" />
      </geometry>
    </collision>
  </link>
  <joint
    name="joint_t"
    type="continuous">
    <origin
      xyz="0 0.051 0"
      rpy="0 0 0" />
    <parent
      link="link_b" />
    <child
      link="link_t" />
    <axis
      xyz="0 1 0" />
    <limit
      lower="-6.28319"
      upper="6.28319"
      effort="0"
      velocity="0" />
  </joint>
</robot>